2022-02-02 11:05:39,502 INFO    MainThread:919 [internal.py:wandb_internal():92] W&B internal server running at pid: 919, started at: 2022-02-02 11:05:39.501734
2022-02-02 11:05:39,504 DEBUG   HandlerThread:919 [handler.py:handle_request():131] handle_request: check_version
2022-02-02 11:05:39,505 INFO    WriterThread:919 [datastore.py:open_for_write():77] open: /work/wandb/run-20220202_110530-xgb_depth_test/run-xgb_depth_test.wandb
2022-02-02 11:05:39,511 DEBUG   SenderThread:919 [sender.py:send():235] send: header
2022-02-02 11:05:39,511 DEBUG   SenderThread:919 [sender.py:send_request():249] send_request: check_version
2022-02-02 11:05:39,546 DEBUG   SenderThread:919 [sender.py:send():235] send: run
2022-02-02 11:05:39,626 ERROR   SenderThread:919 [internal_api.py:execute():143] 404 response executing GraphQL.
2022-02-02 11:05:39,626 ERROR   SenderThread:919 [internal_api.py:execute():144] {"errors":[{"message":"project not found","path":["upsertBucket"]}],"data":{"upsertBucket":null}}
2022-02-02 11:05:40,547 INFO    HandlerThread:919 [handler.py:finish():739] shutting down handler
2022-02-02 11:05:40,549 INFO    WriterThread:919 [datastore.py:close():281] close: /work/wandb/run-20220202_110530-xgb_depth_test/run-xgb_depth_test.wandb
2022-02-02 11:05:40,550 ERROR   MainThread:919 [internal.py:wandb_internal():164] Thread SenderThread:
Traceback (most recent call last):
  File "/root/venv/lib/python3.7/site-packages/wandb/sdk/lib/retry.py", line 102, in __call__
    result = self._call_fn(*args, **kwargs)
  File "/root/venv/lib/python3.7/site-packages/wandb/sdk/internal/internal_api.py", line 146, in execute
    six.reraise(*sys.exc_info())
  File "/shared-libs/python3.7/py-core/lib/python3.7/site-packages/six.py", line 719, in reraise
    raise value
  File "/root/venv/lib/python3.7/site-packages/wandb/sdk/internal/internal_api.py", line 140, in execute
    return self.client.execute(*args, **kwargs)
  File "/root/venv/lib/python3.7/site-packages/wandb/vendor/gql-0.2.0/gql/client.py", line 52, in execute
    result = self._get_result(document, *args, **kwargs)
  File "/root/venv/lib/python3.7/site-packages/wandb/vendor/gql-0.2.0/gql/client.py", line 60, in _get_result
    return self.transport.execute(document, *args, **kwargs)
  File "/root/venv/lib/python3.7/site-packages/wandb/vendor/gql-0.2.0/gql/transport/requests.py", line 39, in execute
    request.raise_for_status()
  File "/shared-libs/python3.7/py/lib/python3.7/site-packages/requests/models.py", line 953, in raise_for_status
    raise HTTPError(http_error_msg, response=self)
requests.exceptions.HTTPError: 404 Client Error: Not Found for url: https://api.wandb.ai/graphql

During handling of the above exception, another exception occurred:

Traceback (most recent call last):
  File "/root/venv/lib/python3.7/site-packages/wandb/apis/normalize.py", line 24, in wrapper
    return func(*args, **kwargs)
  File "/root/venv/lib/python3.7/site-packages/wandb/sdk/internal/internal_api.py", line 1296, in upsert_run
    response = self.gql(mutation, variable_values=variable_values, **kwargs)
  File "/root/venv/lib/python3.7/site-packages/wandb/sdk/lib/retry.py", line 118, in __call__
    if not check_retry_fn(e):
  File "/root/venv/lib/python3.7/site-packages/wandb/util.py", line 821, in no_retry_auth
    raise CommError("Permission denied, ask the project owner to grant you access")
wandb.errors.CommError: Permission denied, ask the project owner to grant you access

During handling of the above exception, another exception occurred:

Traceback (most recent call last):
  File "/root/venv/lib/python3.7/site-packages/wandb/sdk/internal/internal_util.py", line 54, in run
    self._run()
  File "/root/venv/lib/python3.7/site-packages/wandb/sdk/internal/internal_util.py", line 105, in _run
    self._process(record)
  File "/root/venv/lib/python3.7/site-packages/wandb/sdk/internal/internal.py", line 305, in _process
    self._sm.send(record)
  File "/root/venv/lib/python3.7/site-packages/wandb/sdk/internal/sender.py", line 237, in send
    send_handler(record)
  File "/root/venv/lib/python3.7/site-packages/wandb/sdk/internal/sender.py", line 692, in send_run
    self._init_run(run, config_value_dict)
  File "/root/venv/lib/python3.7/site-packages/wandb/sdk/internal/sender.py", line 730, in _init_run
    commit=run.git.last_commit or None,
  File "/root/venv/lib/python3.7/site-packages/wandb/apis/normalize.py", line 62, in wrapper
    six.reraise(CommError, CommError(message, err), sys.exc_info()[2])
  File "/shared-libs/python3.7/py-core/lib/python3.7/site-packages/six.py", line 718, in reraise
    raise value.with_traceback(tb)
  File "/root/venv/lib/python3.7/site-packages/wandb/apis/normalize.py", line 24, in wrapper
    return func(*args, **kwargs)
  File "/root/venv/lib/python3.7/site-packages/wandb/sdk/internal/internal_api.py", line 1296, in upsert_run
    response = self.gql(mutation, variable_values=variable_values, **kwargs)
  File "/root/venv/lib/python3.7/site-packages/wandb/sdk/lib/retry.py", line 118, in __call__
    if not check_retry_fn(e):
  File "/root/venv/lib/python3.7/site-packages/wandb/util.py", line 821, in no_retry_auth
    raise CommError("Permission denied, ask the project owner to grant you access")
wandb.errors.CommError: Permission denied, ask the project owner to grant you access
2022-02-02 11:05:42,580 INFO    MainThread:919 [internal.py:handle_exit():79] Internal process exited
